Workbook

Sheet BOM
M1: Quantity to produce➡️ | N1: 8 | O1: Production➡️ | Q1: Internal
A2: OEPS PN | B2: Schematic Name⬇️ | C2: Qtty.⬇️ | D2: Description | E2: Type | F2: Manufacturer PN⬇️ | G2: Supplier | H2: Supplier PN | I2: Notes⬇️ | J2: Losses | K2: Needed | L2: To order | M2: Stock RM | N2: Packages | O2: Internal | Q2: External
B3: PCB COMPONENTS
A4: =IF($D4="","",VLOOKUP($D4,'components list'!$A$1:$G$1000,2,FALSE())) -> OEPS010011 | B4: C3, C4 | C4: 2 | D4: {=IF(ISBLANK($F4),"",INDIRECT("components list!A"&match(F4,'components list'!$D$1:$D$1000,0)))} -> CAPACITOR: SMD CER 0402 47pF 50V ±5% C0G [04025A470JAT2A] [SMD] | E4: =IF($D4="","",VLOOKUP($D4,'components list'!$A$1:$G$1000,3,FALSE())) -> SMD | F4: 04025A470JAT2A | G4: =IF($D4="","",VLOOKUP($D4,'components list'!$A$1:$G$1000,6,FALSE())) -> DigiKey | H4: =IF($D4="","",VLOOKUP($D4,'components list'!$A$1:$G$1000,7,FALSE())) -> 478-1078-6-ND | J4: =IF(AND(NOT($D4=""),ISNUMBER(C4)),IF($Q$1="Internal",0,VLOOKUP($D4,'components list'!$A$1:$G$1000,5,FALSE())),"") -> 0 | K4: =if(isnumber(L4),if($Q$1="Internal",C4*$N$1,C4*$N$1+J4),"") -> 16 | L4: =IF(AND(NOT(ISBLANK($D4)),ISNUMBER(C4)),IF(C4>0,MAX(0,C4*$N$1+J4-M4),0),"") -> 16 | M4: =IFNA(IF(ISBLANK($A4),"",VLOOKUP($A4,'components list'!$N$1:$AM$10000,4,FALSE())),"") | N4: =IFNA(IF(ISBLANK($A4),"",VLOOKUP($A4,'components list'!$N$1:$AM$10000,3,FALSE())),"") | O4: =if(isnumber(L4),MAX(0,rounddown(M4/C4,0)),"") -> 0 | P4: =if(O4>=$N$1,"OK","NOK") -> NOK | Q4: =if(isnumber(L4),max(0,rounddown((M4-VLOOKUP($D4,'components list'!$A$1:$G$1000,5,FALSE()))/C4,0)),"") -> 0 | R4: =if(Q4>=$N$1,"OK","NOK") -> NOK
A5: =IF($D5="","",VLOOKUP($D5,'components list'!$A$1:$G$1000,2,FALSE())) -> OEPS010017 | B5: C1 | C5: 1 | D5: {=IF(ISBLANK($F5),"",INDIRECT("components list!A"&match(F5,'components list'!$D$1:$D$1000,0)))} -> CAPACITOR: SMD CER 0402 4.7nF 100V ±10% X7R [885012205084] [SMD] | E5: =IF($D5="","",VLOOKUP($D5,'components list'!$A$1:$G$1000,3,FALSE())) -> SMD | F5: 885012205084 | G5: =IF($D5="","",VLOOKUP($D5,'components list'!$A$1:$G$1000,6,FALSE())) -> DigiKey | H5: =IF($D5="","",VLOOKUP($D5,'components list'!$A$1:$G$1000,7,FALSE())) -> 732-12234-6-ND | J5: =IF(AND(NOT($D5=""),ISNUMBER(C5)),IF($Q$1="Internal",0,VLOOKUP($D5,'components list'!$A$1:$G$1000,5,FALSE())),"") -> 0 | K5: =if(isnumber(L5),if($Q$1="Internal",C5*$N$1,C5*$N$1+J5),"") -> 8 | L5: =IF(AND(NOT(ISBLANK($D5)),ISNUMBER(C5)),IF(C5>0,MAX(0,C5*$N$1+J5-M5),0),"") -> 0 | M5: =IFNA(IF(ISBLANK($A5),"",VLOOKUP($A5,'components list'!$N$1:$AM$10000,4,FALSE())),"") -> 15 | N5: =IFNA(IF(ISBLANK($A5),"",VLOOKUP($A5,'components list'!$N$1:$AM$10000,3,FALSE())),"") -> 6(Tp) 9(Tp) | O5: =if(isnumber(L5),MAX(0,rounddown(M5/C5,0)),"") -> 15 | P5: =if(O5>=$N$1,"OK","NOK") -> OK | Q5: =if(isnumber(L5),max(0,rounddown((M5-VLOOKUP($D5,'components list'!$A$1:$G$1000,5,FALSE()))/C5,0)),"") -> 0 | R5: =if(Q5>=$N$1,"OK","NOK") -> NOK
A6: =IF($D6="","",VLOOKUP($D6,'components list'!$A$1:$G$1000,2,FALSE())) -> OEPS010016 | B6: C2, C6, C8, C9, C10, C12, C13, C14, C15, C16, C21 | C6: 11 | D6: {=IF(ISBLANK($F6),"",INDIRECT("components list!A"&match(F6,'components list'!$D$1:$D$1000,0)))} -> CAPACITOR: SMD CER 0402 100nF 50V ±10% X7R [CGA2B3X7R1H104K050BB] [SMD] | E6: =IF($D6="","",VLOOKUP($D6,'components list'!$A$1:$G$1000,3,FALSE())) -> SMD | F6: CGA2B3X7R1H104K050BB | G6: =IF($D6="","",VLOOKUP($D6,'components list'!$A$1:$G$1000,6,FALSE())) -> DigiKey | H6: =IF($D6="","",VLOOKUP($D6,'components list'!$A$1:$G$1000,7,FALSE())) -> 445-6899-6-ND | J6: =IF(AND(NOT($D6=""),ISNUMBER(C6)),IF($Q$1="Internal",0,VLOOKUP($D6,'components list'!$A$1:$G$1000,5,FALSE())),"") -> 0 | K6: =if(isnumber(L6),if($Q$1="Internal",C6*$N$1,C6*$N$1+J6),"") -> 88 | L6: =IF(AND(NOT(ISBLANK($D6)),ISNUMBER(C6)),IF(C6>0,MAX(0,C6*$N$1+J6-M6),0),"") -> 85 | M6: =IFNA(IF(ISBLANK($A6),"",VLOOKUP($A6,'components list'!$N$1:$AM$10000,4,FALSE())),"") -> 3 | N6: =IFNA(IF(ISBLANK($A6),"",VLOOKUP($A6,'components list'!$N$1:$AM$10000,3,FALSE())),"") -> 3(Tp) | O6: =if(isnumber(L6),MAX(0,rounddown(M6/C6,0)),"") -> 0 | P6: =if(O6>=$N$1,"OK","NOK") -> NOK | Q6: =if(isnumber(L6),max(0,rounddown((M6-VLOOKUP($D6,'components list'!$A$1:$G$1000,5,FALSE()))/C6,0)),"") -> 0 | R6: =if(Q6>=$N$1,"OK","NOK") -> NOK
A7: =IF($D7="","",VLOOKUP($D7,'components list'!$A$1:$G$1000,2,FALSE())) -> OEPS010015 | B7: C5, C7, C11, C17 | C7: 4 | D7: {=IF(ISBLANK($F7),"",INDIRECT("components list!A"&match(F7,'components list'!$D$1:$D$1000,0)))} -> CAPACITOR: SMD CER 0603 10uF 16V ±20% X5R [EMK107BBJ106MA-T] [SMD] | E7: =IF($D7="","",VLOOKUP($D7,'components list'!$A$1:$G$1000,3,FALSE())) -> SMD | F7: EMK107BBJ106MA-T | G7: =IF($D7="","",VLOOKUP($D7,'components list'!$A$1:$G$1000,6,FALSE())) -> DigiKey | H7: =IF($D7="","",VLOOKUP($D7,'components list'!$A$1:$G$1000,7,FALSE())) -> 587-3238-6-ND | J7: =IF(AND(NOT($D7=""),ISNUMBER(C7)),IF($Q$1="Internal",0,VLOOKUP($D7,'components list'!$A$1:$G$1000,5,FALSE())),"") -> 0 | K7: =if(isnumber(L7),if($Q$1="Internal",C7*$N$1,C7*$N$1+J7),"") -> 32 | L7: =IF(AND(NOT(ISBLANK($D7)),ISNUMBER(C7)),IF(C7>0,MAX(0,C7*$N$1+J7-M7),0),"") -> 0 | M7: =IFNA(IF(ISBLANK($A7),"",VLOOKUP($A7,'components list'!$N$1:$AM$10000,4,FALSE())),"") -> 53 | N7: =IFNA(IF(ISBLANK($A7),"",VLOOKUP($A7,'components list'!$N$1:$AM$10000,3,FALSE())),"") -> 4(Tp) 49(Tp) | O7: =if(isnumber(L7),MAX(0,rounddown(M7/C7,0)),"") -> 13 | P7: =if(O7>=$N$1,"OK","NOK") -> OK | Q7: =if(isnumber(L7),max(0,rounddown((M7-VLOOKUP($D7,'components list'!$A$1:$G$1000,5,FALSE()))/C7,0)),"") -> 8 | R7: =if(Q7>=$N$1,"OK","NOK") -> OK
A8: =IF($D8="","",VLOOKUP($D8,'components list'!$A$1:$G$1000,2,FALSE())) -> OEPS210002 | B8: C18, C19, C20 | C8: 3 | D8: {=IF(ISBLANK($F8),"",INDIRECT("components list!A"&match(F8,'components list'!$D$1:$D$1000,0)))} -> CAPACITOR POL: SMD TANT A 1206 100uF 10V ±20% 1.4Ohm [TLJA107M010R1400] [SMD] | E8: =IF($D8="","",VLOOKUP($D8,'components list'!$A$1:$G$1000,3,FALSE())) -> SMD | F8: TLJA107M010R1400 | G8: =IF($D8="","",VLOOKUP($D8,'components list'!$A$1:$G$1000,6,FALSE())) -> DigiKey | H8: =IF($D8="","",VLOOKUP($D8,'components list'!$A$1:$G$1000,7,FALSE())) -> 478-5651-6-ND | J8: =IF(AND(NOT($D8=""),ISNUMBER(C8)),IF($Q$1="Internal",0,VLOOKUP($D8,'components list'!$A$1:$G$1000,5,FALSE())),"") -> 0 | K8: =if(isnumber(L8),if($Q$1="Internal",C8*$N$1,C8*$N$1+J8),"") -> 24 | L8: =IF(AND(NOT(ISBLANK($D8)),ISNUMBER(C8)),IF(C8>0,MAX(0,C8*$N$1+J8-M8),0),"") -> 24 | M8: =IFNA(IF(ISBLANK($A8),"",VLOOKUP($A8,'components list'!$N$1:$AM$10000,4,FALSE())),"") | N8: =IFNA(IF(ISBLANK($A8),"",VLOOKUP($A8,'components list'!$N$1:$AM$10000,3,FALSE())),"") | O8: =if(isnumber(L8),MAX(0,rounddown(M8/C8,0)),"") -> 0 | P8: =if(O8>=$N$1,"OK","NOK") -> NOK | Q8: =if(isnumber(L8),max(0,rounddown((M8-VLOOKUP($D8,'components list'!$A$1:$G$1000,5,FALSE()))/C8,0)),"") -> 0 | R8: =if(Q8>=$N$1,"OK","NOK") -> NOK
A9: =IF($D9="","",VLOOKUP($D9,'components list'!$A$1:$G$1000,2,FALSE())) -> OEPS020034 | B9: R7 | C9: 1 | D9: {=IF(ISBLANK($F9),"",INDIRECT("components list!A"&match(F9,'components list'!$D$1:$D$1000,0)))} -> RESISTOR: SMD 0402 39Ω ±1% 0.250W [RCS040239R0FKED] [SMD] | E9: =IF($D9="","",VLOOKUP($D9,'components list'!$A$1:$G$1000,3,FALSE())) -> SMD | F9: RCS040239R0FKED | G9: =IF($D9="","",VLOOKUP($D9,'components list'!$A$1:$G$1000,6,FALSE())) -> DigiKey | H9: =IF($D9="","",VLOOKUP($D9,'components list'!$A$1:$G$1000,7,FALSE())) -> 541-10407-6-ND | J9: =IF(AND(NOT($D9=""),ISNUMBER(C9)),IF($Q$1="Internal",0,VLOOKUP($D9,'components list'!$A$1:$G$1000,5,FALSE())),"") -> 0 | K9: =if(isnumber(L9),if($Q$1="Internal",C9*$N$1,C9*$N$1+J9),"") -> 8 | L9: =IF(AND(NOT(ISBLANK($D9)),ISNUMBER(C9)),IF(C9>0,MAX(0,C9*$N$1+J9-M9),0),"") -> 0 | M9: =IFNA(IF(ISBLANK($A9),"",VLOOKUP($A9,'components list'!$N$1:$AM$10000,4,FALSE())),"") -> 13 | N9: =IFNA(IF(ISBLANK($A9),"",VLOOKUP($A9,'components list'!$N$1:$AM$10000,3,FALSE())),"") -> 10(Tp) 3(Tp) | O9: =if(isnumber(L9),MAX(0,rounddown(M9/C9,0)),"") -> 13 | P9: =if(O9>=$N$1,"OK","NOK") -> OK | Q9: =if(isnumber(L9),max(0,rounddown((M9-VLOOKUP($D9,'components list'!$A$1:$G$1000,5,FALSE()))/C9,0)),"") -> 0 | R9: =if(Q9>=$N$1,"OK","NOK") -> NOK
A10: =IF($D10="","",VLOOKUP($D10,'components list'!$A$1:$G$1000,2,FALSE())) -> OEPS020027 | B10: R2, R3, R4, R6, R8 | C10: 5 | D10: {=IF(ISBLANK($F10),"",INDIRECT("components list!A"&match(F10,'components list'!$D$1:$D$1000,0)))} -> RESISTOR: SMD 0402 1kΩ ±1% 0.063W [CRCW04021K00FKED] [SMD] | E10: =IF($D10="","",VLOOKUP($D10,'components list'!$A$1:$G$1000,3,FALSE())) -> SMD | F10: CRCW04021K00FKED | G10: =IF($D10="","",VLOOKUP($D10,'components list'!$A$1:$G$1000,6,FALSE())) -> DigiKey | H10: =IF($D10="","",VLOOKUP($D10,'components list'!$A$1:$G$1000,7,FALSE())) -> 541-1.00KLDKR-ND | J10: =IF(AND(NOT($D10=""),ISNUMBER(C10)),IF($Q$1="Internal",0,VLOOKUP($D10,'components list'!$A$1:$G$1000,5,FALSE())),"") -> 0 | K10: =if(isnumber(L10),if($Q$1="Internal",C10*$N$1,C10*$N$1+J10),"") -> 40 | L10: =IF(AND(NOT(ISBLANK($D10)),ISNUMBER(C10)),IF(C10>0,MAX(0,C10*$N$1+J10-M10),0),"") -> 40 | M10: =IFNA(IF(ISBLANK($A10),"",VLOOKUP($A10,'components list'!$N$1:$AM$10000,4,FALSE())),"") | N10: =IFNA(IF(ISBLANK($A10),"",VLOOKUP($A10,'components list'!$N$1:$AM$10000,3,FALSE())),"") | O10: =if(isnumber(L10),MAX(0,rounddown(M10/C10,0)),"") -> 0 | P10: =if(O10>=$N$1,"OK","NOK") -> NOK | Q10: =if(isnumber(L10),max(0,rounddown((M10-VLOOKUP($D10,'components list'!$A$1:$G$1000,5,FALSE()))/C10,0)),"") -> 0 | R10: =if(Q10>=$N$1,"OK","NOK") -> NOK
A11: =IF($D11="","",VLOOKUP($D11,'components list'!$A$1:$G$1000,2,FALSE())) -> OEPS020030 | B11: R5 | C11: 1 | D11: {=IF(ISBLANK($F11),"",INDIRECT("components list!A"&match(F11,'components list'!$D$1:$D$1000,0)))} -> RESISTOR: SMD 0402 10kΩ ±1% 0.063W [CRCW040210K0FKED] [SMD] | E11: =IF($D11="","",VLOOKUP($D11,'components list'!$A$1:$G$1000,3,FALSE())) -> SMD | F11: CRCW040210K0FKED | G11: =IF($D11="","",VLOOKUP($D11,'components list'!$A$1:$G$1000,6,FALSE())) -> DigiKey | H11: =IF($D11="","",VLOOKUP($D11,'components list'!$A$1:$G$1000,7,FALSE())) -> 541-10.0KLDKR-ND | J11: =IF(AND(NOT($D11=""),ISNUMBER(C11)),IF($Q$1="Internal",0,VLOOKUP($D11,'components list'!$A$1:$G$1000,5,FALSE())),"") -> 0 | K11: =if(isnumber(L11),if($Q$1="Internal",C11*$N$1,C11*$N$1+J11),"") -> 8 | L11: =IF(AND(NOT(ISBLANK($D11)),ISNUMBER(C11)),IF(C11>0,MAX(0,C11*$N$1+J11-M11),0),"") -> 7 | M11: =IFNA(IF(ISBLANK($A11),"",VLOOKUP($A11,'components list'!$N$1:$AM$10000,4,FALSE())),"") -> 1 | N11: =IFNA(IF(ISBLANK($A11),"",VLOOKUP($A11,'components list'!$N$1:$AM$10000,3,FALSE())),"") -> 1(Tp) | O11: =if(isnumber(L11),MAX(0,rounddown(M11/C11,0)),"") -> 1 | P11: =if(O11>=$N$1,"OK","NOK") -> NOK | Q11: =if(isnumber(L11),max(0,rounddown((M11-VLOOKUP($D11,'components list'!$A$1:$G$1000,5,FALSE()))/C11,0)),"") -> 0 | R11: =if(Q11>=$N$1,"OK","NOK") -> NOK
A12: =IF($D12="","",VLOOKUP($D12,'components list'!$A$1:$G$1000,2,FALSE())) -> OEPS020026 | B12: R1 | C12: 1 | D12: {=IF(ISBLANK($F12),"",INDIRECT("components list!A"&match(F12,'components list'!$D$1:$D$1000,0)))} -> RESISTOR: SMD 0402 1MΩ ±1% 0.063W [CRCW04021M00FKED] [SMD] | E12: =IF($D12="","",VLOOKUP($D12,'components list'!$A$1:$G$1000,3,FALSE())) -> SMD | F12: CRCW04021M00FKED | G12: =IF($D12="","",VLOOKUP($D12,'components list'!$A$1:$G$1000,6,FALSE())) -> DigiKey | H12: =IF($D12="","",VLOOKUP($D12,'components list'!$A$1:$G$1000,7,FALSE())) -> 541-1.00MLDKR-ND | J12: =IF(AND(NOT($D12=""),ISNUMBER(C12)),IF($Q$1="Internal",0,VLOOKUP($D12,'components list'!$A$1:$G$1000,5,FALSE())),"") -> 0 | K12: =if(isnumber(L12),if($Q$1="Internal",C12*$N$1,C12*$N$1+J12),"") -> 8 | L12: =IF(AND(NOT(ISBLANK($D12)),ISNUMBER(C12)),IF(C12>0,MAX(0,C12*$N$1+J12-M12),0),"") -> 8 | M12: =IFNA(IF(ISBLANK($A12),"",VLOOKUP($A12,'components list'!$N$1:$AM$10000,4,FALSE())),"") | N12: =IFNA(IF(ISBLANK($A12),"",VLOOKUP($A12,'components list'!$N$1:$AM$10000,3,FALSE())),"") | O12: =if(isnumber(L12),MAX(0,rounddown(M12/C12,0)),"") -> 0 | P12: =if(O12>=$N$1,"OK","NOK") -> NOK | Q12: =if(isnumber(L12),max(0,rounddown((M12-VLOOKUP($D12,'components list'!$A$1:$G$1000,5,FALSE()))/C12,0)),"") -> 0 | R12: =if(Q12>=$N$1,"OK","NOK") -> NOK
A13: =IF($D13="","",VLOOKUP($D13,'components list'!$A$1:$G$1000,2,FALSE())) -> OEPS040003 | B13: L1 | C13: 1 | D13: {=IF(ISBLANK($F13),"",INDIRECT("components list!A"&match(F13,'components list'!$D$1:$D$1000,0)))} -> INDUCTOR: FERRITE BEAD SMD 40Ω 2A 50mΩ [MI0805K400R-10] [0805] | E13: =IF($D13="","",VLOOKUP($D13,'components list'!$A$1:$G$1000,3,FALSE())) -> SMD | F13: MI0805K400R-10 | G13: =IF($D13="","",VLOOKUP($D13,'components list'!$A$1:$G$1000,6,FALSE())) -> DigiKey | H13: =IF($D13="","",VLOOKUP($D13,'components list'!$A$1:$G$1000,7,FALSE())) -> 240-2389-6-ND | J13: =IF(AND(NOT($D13=""),ISNUMBER(C13)),IF($Q$1="Internal",0,VLOOKUP($D13,'components list'!$A$1:$G$1000,5,FALSE())),"") -> 0 | K13: =if(isnumber(L13),if($Q$1="Internal",C13*$N$1,C13*$N$1+J13),"") -> 8 | L13: =IF(AND(NOT(ISBLANK($D13)),ISNUMBER(C13)),IF(C13>0,MAX(0,C13*$N$1+J13-M13),0),"") -> 6 | M13: =IFNA(IF(ISBLANK($A13),"",VLOOKUP($A13,'components list'!$N$1:$AM$10000,4,FALSE())),"") -> 2 | N13: =IFNA(IF(ISBLANK($A13),"",VLOOKUP($A13,'components list'!$N$1:$AM$10000,3,FALSE())),"") -> 2(Tp) | O13: =if(isnumber(L13),MAX(0,rounddown(M13/C13,0)),"") -> 2 | P13: =if(O13>=$N$1,"OK","NOK") -> NOK | Q13: =if(isnumber(L13),max(0,rounddown((M13-VLOOKUP($D13,'components list'!$A$1:$G$1000,5,FALSE()))/C13,0)),"") -> 0 | R13: =if(Q13>=$N$1,"OK","NOK") -> NOK
A14: =IF($D14="","",VLOOKUP($D14,'components list'!$A$1:$G$1000,2,FALSE())) -> OEPS060005 | B14: Q1 | C14: 1 | D14: {=IF(ISBLANK($F14),"",INDIRECT("components list!A"&match(F14,'components list'!$D$1:$D$1000,0)))} -> TRANSISTOR: BJT NPN 45V 0.5A [BC817-40W-7] [SOT-323] | E14: =IF($D14="","",VLOOKUP($D14,'components list'!$A$1:$G$1000,3,FALSE())) -> SMD | F14: BC817-40W-7 | G14: =IF($D14="","",VLOOKUP($D14,'components list'!$A$1:$G$1000,6,FALSE())) -> DigiKey | H14: =IF($D14="","",VLOOKUP($D14,'components list'!$A$1:$G$1000,7,FALSE())) -> BC817-40WDIDKR-ND | J14: =IF(AND(NOT($D14=""),ISNUMBER(C14)),IF($Q$1="Internal",0,VLOOKUP($D14,'components list'!$A$1:$G$1000,5,FALSE())),"") -> 0 | K14: =if(isnumber(L14),if($Q$1="Internal",C14*$N$1,C14*$N$1+J14),"") -> 8 | L14: =IF(AND(NOT(ISBLANK($D14)),ISNUMBER(C14)),IF(C14>0,MAX(0,C14*$N$1+J14-M14),0),"") -> 5 | M14: =IFNA(IF(ISBLANK($A14),"",VLOOKUP($A14,'components list'!$N$1:$AM$10000,4,FALSE())),"") -> 3 | N14: =IFNA(IF(ISBLANK($A14),"",VLOOKUP($A14,'components list'!$N$1:$AM$10000,3,FALSE())),"") -> 3(Tp) | O14: =if(isnumber(L14),MAX(0,rounddown(M14/C14,0)),"") -> 3 | P14: =if(O14>=$N$1,"OK","NOK") -> NOK | Q14: =if(isnumber(L14),max(0,rounddown((M14-VLOOKUP($D14,'components list'!$A$1:$G$1000,5,FALSE()))/C14,0)),"") -> 0 | R14: =if(Q14>=$N$1,"OK","NOK") -> NOK
A15: =IF($D15="","",VLOOKUP($D15,'components list'!$A$1:$G$1000,2,FALSE())) -> OEPS060004 | B15: Q2 | C15: 1 | D15: {=IF(ISBLANK($F15),"",INDIRECT("components list!A"&match(F15,'components list'!$D$1:$D$1000,0)))} -> TRANSISTOR: MOSFET P-CH 60V 1.7A [NTF2955T1G] [SOT-223] | E15: =IF($D15="","",VLOOKUP($D15,'components list'!$A$1:$G$1000,3,FALSE())) -> SMD | F15: NTF2955T1G | G15: =IF($D15="","",VLOOKUP($D15,'components list'!$A$1:$G$1000,6,FALSE())) -> DigiKey | H15: =IF($D15="","",VLOOKUP($D15,'components list'!$A$1:$G$1000,7,FALSE())) -> NTF2955T1GOSDKR-ND | J15: =IF(AND(NOT($D15=""),ISNUMBER(C15)),IF($Q$1="Internal",0,VLOOKUP($D15,'components list'!$A$1:$G$1000,5,FALSE())),"") -> 0 | K15: =if(isnumber(L15),if($Q$1="Internal",C15*$N$1,C15*$N$1+J15),"") -> 8 | L15: =IF(AND(NOT(ISBLANK($D15)),ISNUMBER(C15)),IF(C15>0,MAX(0,C15*$N$1+J15-M15),0),"") -> 0 | M15: =IFNA(IF(ISBLANK($A15),"",VLOOKUP($A15,'components list'!$N$1:$AM$10000,4,FALSE())),"") -> 10 | N15: =IFNA(IF(ISBLANK($A15),"",VLOOKUP($A15,'components list'!$N$1:$AM$10000,3,FALSE())),"") -> 10 | O15: =if(isnumber(L15),MAX(0,rounddown(M15/C15,0)),"") -> 10 | P15: =if(O15>=$N$1,"OK","NOK") -> OK | Q15: =if(isnumber(L15),max(0,rounddown((M15-VLOOKUP($D15,'components list'!$A$1:$G$1000,5,FALSE()))/C15,0)),"") -> 7 | R15: =if(Q15>=$N$1,"OK","NOK") -> NOK
... A26: =IF($D26="","",VLOOKUP($D26,'components list'!$A$1:$G$1000,2,FALSE())) -> OEPS070020 | B26: OUT | C26: 1 | D26: {=IF(ISBLANK($F26),"",INDIRECT("components list!A"&match(F26,'components list'!$D$1:$D$1000,0)))} -> CONNECTOR: TERMINAL BLOCK 2.54MM 2POS side entry [282834-2] [TH] | E26: =IF($D26="","",VLOOKUP($D26,'components list'!$A$1:$G$1000,3,FALSE())) -> TH | F26: 282834-2 | G26: =IF($D26="","",VLOOKUP($D26,'components list'!$A$1:$G$1000,6,FALSE())) -> DigiKey | H26: =IF($D26="","",VLOOKUP($D26,'components list'!$A$1:$G$1000,7,FALSE())) -> A98333-ND | J26: =IF(AND(NOT($D26=""),ISNUMBER(C26)),IF($Q$1="Internal",0,VLOOKUP($D26,'components list'!$A$1:$G$1000,5,FALSE())),"") -> 0 | K26: =if(isnumber(L26),if($Q$1="Internal",C26*$N$1,C26*$N$1+J26),"") -> 8 | L26: =IF(AND(NOT(ISBLANK($D26)),ISNUMBER(C26)),IF(C26>0,MAX(0,C26*$N$1+J26-M26),0),"") -> 0 | M26: =IFNA(IF(ISBLANK($A26),"",VLOOKUP($A26,'components list'!$N$1:$AM$10000,4,FALSE())),"") -> 15 | N26: =IFNA(IF(ISBLANK($A26),"",VLOOKUP($A26,'components list'!$N$1:$AM$10000,3,FALSE())),"") -> 10 5 | O26: =if(isnumber(L26),MAX(0,rounddown(M26/C26,0)),"") -> 15 | P26: =if(O26>=$N$1,"OK","NOK") -> OK | Q26: =if(isnumber(L26),max(0,rounddown((M26-VLOOKUP($D26,'components list'!$A$1:$G$1000,5,FALSE()))/C26,0)),"") -> 14 | R26: =if(Q26>=$N$1,"OK","NOK") -> OK
A27: =IF($D27="","",VLOOKUP($D27,'components list'!$A$1:$G$1000,2,FALSE())) | D27: {=IF(ISBLANK($F27),"",INDIRECT("components list!A"&match(F27,'components list'!$D$1:$D$1000,0)))} | E27: =IF($D27="","",VLOOKUP($D27,'components list'!$A$1:$G$1000,3,FALSE())) | G27: =IF($D27="","",VLOOKUP($D27,'components list'!$A$1:$G$1000,6,FALSE())) | H27: =IF($D27="","",VLOOKUP($D27,'components list'!$A$1:$G$1000,7,FALSE())) | J27: =IF(AND(NOT($D27=""),ISNUMBER(C27)),IF($Q$1="Internal",0,VLOOKUP($D27,'components list'!$A$1:$G$1000,5,FALSE())),"") | K27: =if(isnumber(L27),if($Q$1="Internal",C27*$N$1,C27*$N$1+J27),"") | L27: =IF(AND(NOT(ISBLANK($D27)),ISNUMBER(C27)),IF(C27>0,MAX(0,C27*$N$1+J27-M27),0),"") | M27: =IFNA(IF(ISBLANK($A27),"",VLOOKUP($A27,'components list'!$N$1:$AM$10000,4,FALSE())),"") | N27: =IFNA(IF(ISBLANK($A27),"",VLOOKUP($A27,'components list'!$N$1:$AM$10000,3,FALSE())),"") | O27: =if(isnumber(L27),MAX(0,rounddown(M27/C27,0)),"") | P27: =if(O27>=$N$1,"OK","NOK") -> OK | Q27: =if(isnumber(L27),max(0,rounddown((M27-VLOOKUP($D27,'components list'!$A$1:$G$1000,5,FALSE()))/C27,0)),"") | R27: =if(Q27>=$N$1,"OK","NOK") -> OK
A28: =IF($D28="","",VLOOKUP($D28,'components list'!$A$1:$G$1000,2,FALSE())) -> #N/A | C28: 1 | D28: {=IF(ISBLANK($F28),"",INDIRECT("components list!A"&match(F28,'components list'!$D$1:$D$1000,0)))} -> #N/A | E28: =IF($D28="","",VLOOKUP($D28,'components list'!$A$1:$G$1000,3,FALSE())) -> #N/A | F28: E1418287 | G28: =IF($D28="","",VLOOKUP($D28,'components list'!$A$1:$G$1000,6,FALSE())) -> #N/A | H28: =IF($D28="","",VLOOKUP($D28,'components list'!$A$1:$G$1000,7,FALSE())) -> #N/A | J28: =IF(AND(NOT($D28=""),ISNUMBER(C28)),IF($Q$1="Internal",0,VLOOKUP($D28,'components list'!$A$1:$G$1000,5,FALSE())),"") -> #N/A | K28: =if(isnumber(L28),if($Q$1="Internal",C28*$N$1,C28*$N$1+J28),"") | L28: =IF(AND(NOT(ISBLANK($D28)),ISNUMBER(C28)),IF(C28>0,MAX(0,C28*$N$1+J28-M28),0),"") -> #N/A | M28: =IFNA(IF(ISBLANK($A28),"",VLOOKUP($A28,'components list'!$N$1:$AM$10000,4,FALSE())),"") | N28: =IFNA(IF(ISBLANK($A28),"",VLOOKUP($A28,'components list'!$N$1:$AM$10000,3,FALSE())),"") | O28: =if(isnumber(L28),MAX(0,rounddown(M28/C28,0)),"") | P28: =if(O28>=$N$1,"OK","NOK") -> OK | Q28: =if(isnumber(L28),max(0,rounddown((M28-VLOOKUP($D28,'components list'!$A$1:$G$1000,5,FALSE()))/C28,0)),"") | R28: =if(Q28>=$N$1,"OK","NOK") -> OK
A29: =IF($D29="","",VLOOKUP($D29,'components list'!$A$1:$G$1000,2,FALSE())) | D29: {=IF(ISBLANK($F29),"",INDIRECT("components list!A"&match(F29,'components list'!$D$1:$D$1000,0)))} | E29: =IF($D29="","",VLOOKUP($D29,'components list'!$A$1:$G$1000,3,FALSE())) | G29: =IF($D29="","",VLOOKUP($D29,'components list'!$A$1:$G$1000,6,FALSE())) | H29: =IF($D29="","",VLOOKUP($D29,'components list'!$A$1:$G$1000,7,FALSE())) | J29: =IF(AND(NOT($D29=""),ISNUMBER(C29)),IF($Q$1="Internal",0,VLOOKUP($D29,'components list'!$A$1:$G$1000,5,FALSE())),"") | K29: =if(isnumber(L29),if($Q$1="Internal",C29*$N$1,C29*$N$1+J29),"") | L29: =IF(AND(NOT(ISBLANK($D29)),ISNUMBER(C29)),IF(C29>0,MAX(0,C29*$N$1+J29-M29),0),"") | M29: =IFNA(IF(ISBLANK($A29),"",VLOOKUP($A29,'components list'!$N$1:$AM$10000,4,FALSE())),"") | N29: =IFNA(IF(ISBLANK($A29),"",VLOOKUP($A29,'components list'!$N$1:$AM$10000,3,FALSE())),"") | O29: =if(isnumber(L29),MAX(0,rounddown(M29/C29,0)),"") | P29: =if(O29>=$N$1,"OK","NOK") -> OK | Q29: =if(isnumber(L29),max(0,rounddown((M29-VLOOKUP($D29,'components list'!$A$1:$G$1000,5,FALSE()))/C29,0)),"") | R29: =if(Q29>=$N$1,"OK","NOK") -> OK
A30: =IF($D30="","",VLOOKUP($D30,'components list'!$A$1:$G$1000,2,FALSE())) -> OEPS100013 | C30: 1 | D30: {=IF(ISBLANK($F30),"",INDIRECT("components list!A"&match(F30,'components list'!$D$1:$D$1000,0)))} -> OTHER: RFID Reader ID-12LA (125 kHz) [ID-12LA] [TH] | E30: =IF($D30="","",VLOOKUP($D30,'components list'!$A$1:$G$1000,3,FALSE())) -> TH | F30: ID-12LA | G30: =IF($D30="","",VLOOKUP($D30,'components list'!$A$1:$G$1000,6,FALSE())) -> Sparkfun | H30: =IF($D30="","",VLOOKUP($D30,'components list'!$A$1:$G$1000,7,FALSE())) -> SEN-11827 | J30: =IF(AND(NOT($D30=""),ISNUMBER(C30)),IF($Q$1="Internal",0,VLOOKUP($D30,'components list'!$A$1:$G$1000,5,FALSE())),"") -> 0 | K30: =if(isnumber(L30),if($Q$1="Internal",C30*$N$1,C30*$N$1+J30),"") -> 8 | L30: =IF(AND(NOT(ISBLANK($D30)),ISNUMBER(C30)),IF(C30>0,MAX(0,C30*$N$1+J30-M30),0),"") -> 8 | M30: =IFNA(IF(ISBLANK($A30),"",VLOOKUP($A30,'components list'!$N$1:$AM$10000,4,FALSE())),"") | N30: =IFNA(IF(ISBLANK($A30),"",VLOOKUP($A30,'components list'!$N$1:$AM$10000,3,FALSE())),"") | O30: =if(isnumber(L30),MAX(0,rounddown(M30/C30,0)),"") -> 0 | P30: =if(O30>=$N$1,"OK","NOK") -> NOK | Q30: =if(isnumber(L30),max(0,rounddown((M30-VLOOKUP($D30,'components list'!$A$1:$G$1000,5,FALSE()))/C30,0)),"") -> 0 | R30: =if(Q30>=$N$1,"OK","NOK") -> NOK
A31: =IF($D31="","",VLOOKUP($D31,'components list'!$A$1:$G$1000,2,FALSE())) | D31: {=IF(ISBLANK($F31),"",INDIRECT("components list!A"&match(F31,'components list'!$D$1:$D$1000,0)))} | E31: =IF($D31="","",VLOOKUP($D31,'components list'!$A$1:$G$1000,3,FALSE())) | G31: =IF($D31="","",VLOOKUP($D31,'components list'!$A$1:$G$1000,6,FALSE())) | H31: =IF($D31="","",VLOOKUP($D31,'components list'!$A$1:$G$1000,7,FALSE())) | J31: =IF(AND(NOT($D31=""),ISNUMBER(C31)),IF($Q$1="Internal",0,VLOOKUP($D31,'components list'!$A$1:$G$1000,5,FALSE())),"") | K31: =if(isnumber(L31),if($Q$1="Internal",C31*$N$1,C31*$N$1+J31),"") | L31: =IF(AND(NOT(ISBLANK($D31)),ISNUMBER(C31)),IF(C31>0,MAX(0,C31*$N$1+J31-M31),0),"") | M31: =IFNA(IF(ISBLANK($A31),"",VLOOKUP($A31,'components list'!$N$1:$AM$10000,4,FALSE())),"") | N31: =IFNA(IF(ISBLANK($A31),"",VLOOKUP($A31,'components list'!$N$1:$AM$10000,3,FALSE())),"") | O31: =if(isnumber(L31),MAX(0,rounddown(M31/C31,0)),"") | P31: =if(O31>=$N$1,"OK","NOK") -> OK | Q31: =if(isnumber(L31),max(0,rounddown((M31-VLOOKUP($D31,'components list'!$A$1:$G$1000,5,FALSE()))/C31,0)),"") | R31: =if(Q31>=$N$1,"OK","NOK") -> OK
A32: =IF($D32="","",VLOOKUP($D32,'components list'!$A$1:$G$1000,2,FALSE())) | D32: {=IF(ISBLANK($F32),"",INDIRECT("components list!A"&match(F32,'components list'!$D$1:$D$1000,0)))} | E32: =IF($D32="","",VLOOKUP($D32,'components list'!$A$1:$G$1000,3,FALSE())) | G32: =IF($D32="","",VLOOKUP($D32,'components list'!$A$1:$G$1000,6,FALSE())) | H32: =IF($D32="","",VLOOKUP($D32,'components list'!$A$1:$G$1000,7,FALSE())) | J32: =IF(AND(NOT($D32=""),ISNUMBER(C32)),IF($Q$1="Internal",0,VLOOKUP($D32,'components list'!$A$1:$G$1000,5,FALSE())),"") | K32: =if(isnumber(L32),if($Q$1="Internal",C32*$N$1,C32*$N$1+J32),"") | L32: =IF(AND(NOT(ISBLANK($D32)),ISNUMBER(C32)),IF(C32>0,MAX(0,C32*$N$1+J32-M32),0),"") | M32: =IFNA(IF(ISBLANK($A32),"",VLOOKUP($A32,'components list'!$N$1:$AM$10000,4,FALSE())),"") | N32: =IFNA(IF(ISBLANK($A32),"",VLOOKUP($A32,'components list'!$N$1:$AM$10000,3,FALSE())),"") | O32: =if(isnumber(L32),MAX(0,rounddown(M32/C32,0)),"") | P32: =if(O32>=$N$1,"OK","NOK") -> OK | Q32: =if(isnumber(L32),max(0,rounddown((M32-VLOOKUP($D32,'components list'!$A$1:$G$1000,5,FALSE()))/C32,0)),"") | R32: =if(Q32>=$N$1,"OK","NOK") -> OK
A33: =IF($D33="","",VLOOKUP($D33,'components list'!$A$1:$G$1000,2,FALSE())) | D33: {=IF(ISBLANK($F33),"",INDIRECT("components list!A"&match(F33,'components list'!$D$1:$D$1000,0)))} | E33: =IF($D33="","",VLOOKUP($D33,'components list'!$A$1:$G$1000,3,FALSE())) | G33: =IF($D33="","",VLOOKUP($D33,'components list'!$A$1:$G$1000,6,FALSE())) | H33: =IF($D33="","",VLOOKUP($D33,'components list'!$A$1:$G$1000,7,FALSE())) | J33: =IF(AND(NOT($D33=""),ISNUMBER(C33)),IF($Q$1="Internal",0,VLOOKUP($D33,'components list'!$A$1:$G$1000,5,FALSE())),"") | K33: =if(isnumber(L33),if($Q$1="Internal",C33*$N$1,C33*$N$1+J33),"") | L33: =IF(AND(NOT(ISBLANK($D33)),ISNUMBER(C33)),IF(C33>0,MAX(0,C33*$N$1+J33-M33),0),"") | M33: =IFNA(IF(ISBLANK($A33),"",VLOOKUP($A33,'components list'!$N$1:$AM$10000,4,FALSE())),"") | N33: =IFNA(IF(ISBLANK($A33),"",VLOOKUP($A33,'components list'!$N$1:$AM$10000,3,FALSE())),"") | O33: =if(isnumber(L33),MAX(0,rounddown(M33/C33,0)),"") | P33: =if(O33>=$N$1,"OK","NOK") -> OK | Q33: =if(isnumber(L33),max(0,rounddown((M33-VLOOKUP($D33,'components list'!$A$1:$G$1000,5,FALSE()))/C33,0)),"") | R33: =if(Q33>=$N$1,"OK","NOK") -> OK
A34: =IF($D34="","",VLOOKUP($D34,'components list'!$A$1:$G$1000,2,FALSE())) | D34: {=IF(ISBLANK($F34),"",INDIRECT("components list!A"&match(F34,'components list'!$D$1:$D$1000,0)))} | E34: =IF($D34="","",VLOOKUP($D34,'components list'!$A$1:$G$1000,3,FALSE())) | G34: =IF($D34="","",VLOOKUP($D34,'components list'!$A$1:$G$1000,6,FALSE())) | H34: =IF($D34="","",VLOOKUP($D34,'components list'!$A$1:$G$1000,7,FALSE())) | J34: =IF(AND(NOT($D34=""),ISNUMBER(C34)),IF($Q$1="Internal",0,VLOOKUP($D34,'components list'!$A$1:$G$1000,5,FALSE())),"") | K34: =if(isnumber(L34),if($Q$1="Internal",C34*$N$1,C34*$N$1+J34),"") | L34: =IF(AND(NOT(ISBLANK($D34)),ISNUMBER(C34)),IF(C34>0,MAX(0,C34*$N$1+J34-M34),0),"") | M34: =IFNA(IF(ISBLANK($A34),"",VLOOKUP($A34,'components list'!$N$1:$AM$10000,4,FALSE())),"") | N34: =IFNA(IF(ISBLANK($A34),"",VLOOKUP($A34,'components list'!$N$1:$AM$10000,3,FALSE())),"") | O34: =if(isnumber(L34),MAX(0,rounddown(M34/C34,0)),"") | P34: =if(O34>=$N$1,"OK","NOK") -> OK | Q34: =if(isnumber(L34),max(0,rounddown((M34-VLOOKUP($D34,'components list'!$A$1:$G$1000,5,FALSE()))/C34,0)),"") | R34: =if(Q34>=$N$1,"OK","NOK") -> OK
A35: =IF($D35="","",VLOOKUP($D35,'components list'!$A$1:$G$1000,2,FALSE())) | D35: {=IF(ISBLANK($F35),"",INDIRECT("components list!A"&match(F35,'components list'!$D$1:$D$1000,0)))} | E35: =IF($D35="","",VLOOKUP($D35,'components list'!$A$1:$G$1000,3,FALSE())) | G35: =IF($D35="","",VLOOKUP($D35,'components list'!$A$1:$G$1000,6,FALSE())) | H35: =IF($D35="","",VLOOKUP($D35,'components list'!$A$1:$G$1000,7,FALSE())) | J35: =IF(AND(NOT($D35=""),ISNUMBER(C35)),IF($Q$1="Internal",0,VLOOKUP($D35,'components list'!$A$1:$G$1000,5,FALSE())),"") | K35: =if(isnumber(L35),if($Q$1="Internal",C35*$N$1,C35*$N$1+J35),"") | L35: =IF(AND(NOT(ISBLANK($D35)),ISNUMBER(C35)),IF(C35>0,MAX(0,C35*$N$1+J35-M35),0),"") | M35: =IFNA(IF(ISBLANK($A35),"",VLOOKUP($A35,'components list'!$N$1:$AM$10000,4,FALSE())),"") | N35: =IFNA(IF(ISBLANK($A35),"",VLOOKUP($A35,'components list'!$N$1:$AM$10000,3,FALSE())),"") | O35: =if(isnumber(L35),MAX(0,rounddown(M35/C35,0)),"") | P35: =if(O35>=$N$1,"OK","NOK") -> OK | Q35: =if(isnumber(L35),max(0,rounddown((M35-VLOOKUP($D35,'components list'!$A$1:$G$1000,5,FALSE()))/C35,0)),"") | R35: =if(Q35>=$N$1,"OK","NOK") -> OK
A36: =IF($D36="","",VLOOKUP($D36,'components list'!$A$1:$G$1000,2,FALSE())) | D36: {=IF(ISBLANK($F36),"",INDIRECT("components list!A"&match(F36,'components list'!$D$1:$D$1000,0)))} | E36: =IF($D36="","",VLOOKUP($D36,'components list'!$A$1:$G$1000,3,FALSE())) | G36: =IF($D36="","",VLOOKUP($D36,'components list'!$A$1:$G$1000,6,FALSE())) | H36: =IF($D36="","",VLOOKUP($D36,'components list'!$A$1:$G$1000,7,FALSE())) | J36: =IF(AND(NOT($D36=""),ISNUMBER(C36)),IF($Q$1="Internal",0,VLOOKUP($D36,'components list'!$A$1:$G$1000,5,FALSE())),"") | K36: =if(isnumber(L36),if($Q$1="Internal",C36*$N$1,C36*$N$1+J36),"") | L36: =IF(AND(NOT(ISBLANK($D36)),ISNUMBER(C36)),IF(C36>0,MAX(0,C36*$N$1+J36-M36),0),"") | M36: =IFNA(IF(ISBLANK($A36),"",VLOOKUP($A36,'components list'!$N$1:$AM$10000,4,FALSE())),"") | N36: =IFNA(IF(ISBLANK($A36),"",VLOOKUP($A36,'components list'!$N$1:$AM$10000,3,FALSE())),"") | O36: =if(isnumber(L36),MAX(0,rounddown(M36/C36,0)),"") | P36: =if(O36>=$N$1,"OK","NOK") -> OK | Q36: =if(isnumber(L36),max(0,rounddown((M36-VLOOKUP($D36,'components list'!$A$1:$G$1000,5,FALSE()))/C36,0)),"") | R36: =if(Q36>=$N$1,"OK","NOK") -> OK
A37: =IF($D37="","",VLOOKUP($D37,'components list'!$A$1:$G$1000,2,FALSE())) | D37: {=IF(ISBLANK($F37),"",INDIRECT("components list!A"&match(F37,'components list'!$D$1:$D$1000,0)))} | E37: =IF($D37="","",VLOOKUP($D37,'components list'!$A$1:$G$1000,3,FALSE())) | G37: =IF($D37="","",VLOOKUP($D37,'components list'!$A$1:$G$1000,6,FALSE())) | H37: =IF($D37="","",VLOOKUP($D37,'components list'!$A$1:$G$1000,7,FALSE())) | J37: =IF(AND(NOT($D37=""),ISNUMBER(C37)),IF($Q$1="Internal",0,VLOOKUP($D37,'components list'!$A$1:$G$1000,5,FALSE())),"") | K37: =if(isnumber(L37),if($Q$1="Internal",C37*$N$1,C37*$N$1+J37),"") | L37: =IF(AND(NOT(ISBLANK($D37)),ISNUMBER(C37)),IF(C37>0,MAX(0,C37*$N$1+J37-M37),0),"") | M37: =IFNA(IF(ISBLANK($A37),"",VLOOKUP($A37,'components list'!$N$1:$AM$10000,4,FALSE())),"") | N37: =IFNA(IF(ISBLANK($A37),"",VLOOKUP($A37,'components list'!$N$1:$AM$10000,3,FALSE())),"") | O37: =if(isnumber(L37),MAX(0,rounddown(M37/C37,0)),"") | P37: =if(O37>=$N$1,"OK","NOK") -> OK | Q37: =if(isnumber(L37),max(0,rounddown((M37-VLOOKUP($D37,'components list'!$A$1:$G$1000,5,FALSE()))/C37,0)),"") | R37: =if(Q37>=$N$1,"OK","NOK") -> OK
A38: =IF($D38="","",VLOOKUP($D38,'components list'!$A$1:$G$1000,2,FALSE())) | D38: {=IF(ISBLANK($F38),"",INDIRECT("components list!A"&match(F38,'components list'!$D$1:$D$1000,0)))} | E38: =IF($D38="","",VLOOKUP($D38,'components list'!$A$1:$G$1000,3,FALSE())) | G38: =IF($D38="","",VLOOKUP($D38,'components list'!$A$1:$G$1000,6,FALSE())) | H38: =IF($D38="","",VLOOKUP($D38,'components list'!$A$1:$G$1000,7,FALSE())) | J38: =IF(AND(NOT($D38=""),ISNUMBER(C38)),IF($Q$1="Internal",0,VLOOKUP($D38,'components list'!$A$1:$G$1000,5,FALSE())),"") | K38: =if(isnumber(L38),if($Q$1="Internal",C38*$N$1,C38*$N$1+J38),"") | L38: =IF(AND(NOT(ISBLANK($D38)),ISNUMBER(C38)),IF(C38>0,MAX(0,C38*$N$1+J38-M38),0),"") | M38: =IFNA(IF(ISBLANK($A38),"",VLOOKUP($A38,'components list'!$N$1:$AM$10000,4,FALSE())),"") | N38: =IFNA(IF(ISBLANK($A38),"",VLOOKUP($A38,'components list'!$N$1:$AM$10000,3,FALSE())),"") | O38: =if(isnumber(L38),MAX(0,rounddown(M38/C38,0)),"") | P38: =if(O38>=$N$1,"OK","NOK") -> OK | Q38: =if(isnumber(L38),max(0,rounddown((M38-VLOOKUP($D38,'components list'!$A$1:$G$1000,5,FALSE()))/C38,0)),"") | R38: =if(Q38>=$N$1,"OK","NOK") -> OK
A39: =IF($D39="","",VLOOKUP($D39,'components list'!$A$1:$G$1000,2,FALSE())) | D39: {=IF(ISBLANK($F39),"",INDIRECT("components list!A"&match(F39,'components list'!$D$1:$D$1000,0)))} | E39: =IF($D39="","",VLOOKUP($D39,'components list'!$A$1:$G$1000,3,FALSE())) | G39: =IF($D39="","",VLOOKUP($D39,'components list'!$A$1:$G$1000,6,FALSE())) | H39: =IF($D39="","",VLOOKUP($D39,'components list'!$A$1:$G$1000,7,FALSE())) | J39: =IF(AND(NOT($D39=""),ISNUMBER(C39)),IF($Q$1="Internal",0,VLOOKUP($D39,'components list'!$A$1:$G$1000,5,FALSE())),"") | K39: =if(isnumber(L39),if($Q$1="Internal",C39*$N$1,C39*$N$1+J39),"") | L39: =IF(AND(NOT(ISBLANK($D39)),ISNUMBER(C39)),IF(C39>0,MAX(0,C39*$N$1+J39-M39),0),"") | M39: =IFNA(IF(ISBLANK($A39),"",VLOOKUP($A39,'components list'!$N$1:$AM$10000,4,FALSE())),"") | N39: =IFNA(IF(ISBLANK($A39),"",VLOOKUP($A39,'components list'!$N$1:$AM$10000,3,FALSE())),"") | O39: =if(isnumber(L39),MAX(0,rounddown(M39/C39,0)),"") | P39: =if(O39>=$N$1,"OK","NOK") -> OK | Q39: =if(isnumber(L39),max(0,rounddown((M39-VLOOKUP($D39,'components list'!$A$1:$G$1000,5,FALSE()))/C39,0)),"") | R39: =if(Q39>=$N$1,"OK","NOK") -> OK
A40: =IF($D40="","",VLOOKUP($D40,'components list'!$A$1:$G$1000,2,FALSE())) | D40: {=IF(ISBLANK($F40),"",INDIRECT("components list!A"&match(F40,'components list'!$D$1:$D$1000,0)))} | E40: =IF($D40="","",VLOOKUP($D40,'components list'!$A$1:$G$1000,3,FALSE())) | G40: =IF($D40="","",VLOOKUP($D40,'components list'!$A$1:$G$1000,6,FALSE())) | H40: =IF($D40="","",VLOOKUP($D40,'components list'!$A$1:$G$1000,7,FALSE())) | J40: =IF(AND(NOT($D40=""),ISNUMBER(C40)),IF($Q$1="Internal",0,VLOOKUP($D40,'components list'!$A$1:$G$1000,5,FALSE())),"") | K40: =if(isnumber(L40),if($Q$1="Internal",C40*$N$1,C40*$N$1+J40),"") | L40: =IF(AND(NOT(ISBLANK($D40)),ISNUMBER(C40)),IF(C40>0,MAX(0,C40*$N$1+J40-M40),0),"") | M40: =IFNA(IF(ISBLANK($A40),"",VLOOKUP($A40,'components list'!$N$1:$AM$10000,4,FALSE())),"") | N40: =IFNA(IF(ISBLANK($A40),"",VLOOKUP($A40,'components list'!$N$1:$AM$10000,3,FALSE())),"") | O40: =if(isnumber(L40),MAX(0,rounddown(M40/C40,0)),"") | P40: =if(O40>=$N$1,"OK","NOK") -> OK | Q40: =if(isnumber(L40),max(0,rounddown((M40-VLOOKUP($D40,'components list'!$A$1:$G$1000,5,FALSE()))/C40,0)),"") | R40: =if(Q40>=$N$1,"OK","NOK") -> OK
A41: =IF($D41="","",VLOOKUP($D41,'components list'!$A$1:$G$1000,2,FALSE())) | D41: {=IF(ISBLANK($F41),"",INDIRECT("components list!A"&match(F41,'components list'!$D$1:$D$1000,0)))} | E41: =IF($D41="","",VLOOKUP($D41,'components list'!$A$1:$G$1000,3,FALSE())) | G41: =IF($D41="","",VLOOKUP($D41,'components list'!$A$1:$G$1000,6,FALSE())) | H41: =IF($D41="","",VLOOKUP($D41,'components list'!$A$1:$G$1000,7,FALSE())) | J41: =IF(AND(NOT($D41=""),ISNUMBER(C41)),IF($Q$1="Internal",0,VLOOKUP($D41,'components list'!$A$1:$G$1000,5,FALSE())),"") | K41: =if(isnumber(L41),if($Q$1="Internal",C41*$N$1,C41*$N$1+J41),"") | L41: =IF(AND(NOT(ISBLANK($D41)),ISNUMBER(C41)),IF(C41>0,MAX(0,C41*$N$1+J41-M41),0),"") | M41: =IFNA(IF(ISBLANK($A41),"",VLOOKUP($A41,'components list'!$N$1:$AM$10000,4,FALSE())),"") | N41: =IFNA(IF(ISBLANK($A41),"",VLOOKUP($A41,'components list'!$N$1:$AM$10000,3,FALSE())),"") | O41: =if(isnumber(L41),MAX(0,rounddown(M41/C41,0)),"") | P41: =if(O41>=$N$1,"OK","NOK") -> OK | Q41: =if(isnumber(L41),max(0,rounddown((M41-VLOOKUP($D41,'components list'!$A$1:$G$1000,5,FALSE()))/C41,0)),"") | R41: =if(Q41>=$N$1,"OK","NOK") -> OK
A42: =IF($D42="","",VLOOKUP($D42,'components list'!$A$1:$G$1000,2,FALSE())) | D42: {=IF(ISBLANK($F42),"",INDIRECT("components list!A"&match(F42,'components list'!$D$1:$D$1000,0)))} | E42: =IF($D42="","",VLOOKUP($D42,'components list'!$A$1:$G$1000,3,FALSE())) | G42: =IF($D42="","",VLOOKUP($D42,'components list'!$A$1:$G$1000,6,FALSE())) | H42: =IF($D42="","",VLOOKUP($D42,'components list'!$A$1:$G$1000,7,FALSE())) | J42: =IF(AND(NOT($D42=""),ISNUMBER(C42)),IF($Q$1="Internal",0,VLOOKUP($D42,'components list'!$A$1:$G$1000,5,FALSE())),"") | K42: =if(isnumber(L42),if($Q$1="Internal",C42*$N$1,C42*$N$1+J42),"") | L42: =IF(AND(NOT(ISBLANK($D42)),ISNUMBER(C42)),IF(C42>0,MAX(0,C42*$N$1+J42-M42),0),"") | M42: =IFNA(IF(ISBLANK($A42),"",VLOOKUP($A42,'components list'!$N$1:$AM$10000,4,FALSE())),"") | N42: =IFNA(IF(ISBLANK($A42),"",VLOOKUP($A42,'components list'!$N$1:$AM$10000,3,FALSE())),"") | O42: =if(isnumber(L42),MAX(0,rounddown(M42/C42,0)),"") | P42: =if(O42>=$N$1,"OK","NOK") -> OK | Q42: =if(isnumber(L42),max(0,rounddown((M42-VLOOKUP($D42,'components list'!$A$1:$G$1000,5,FALSE()))/C42,0)),"") | R42: =if(Q42>=$N$1,"OK","NOK") -> OK
... A54: =IF($D54="","",VLOOKUP($D54,'components list'!$A$1:$G$1000,2,FALSE())) | D54: {=IF(ISBLANK($F54),"",INDIRECT("components list!A"&match(F54,'components list'!$D$1:$D$1000,0)))} | E54: =IF($D54="","",VLOOKUP($D54,'components list'!$A$1:$G$1000,3,FALSE())) | G54: =IF($D54="","",VLOOKUP($D54,'components list'!$A$1:$G$1000,6,FALSE())) | H54: =IF($D54="","",VLOOKUP($D54,'components list'!$A$1:$G$1000,7,FALSE())) | J54: =IF(AND(NOT($D54=""),ISNUMBER(C54)),IF($Q$1="Internal",0,VLOOKUP($D54,'components list'!$A$1:$G$1000,5,FALSE())),"") | K54: =if(isnumber(L54),if($Q$1="Internal",C54*$N$1,C54*$N$1+J54),"") | L54: =IF(AND(NOT(ISBLANK($D54)),ISNUMBER(C54)),IF(C54>0,MAX(0,C54*$N$1+J54-M54),0),"") | M54: =IFNA(IF(ISBLANK($A54),"",VLOOKUP($A54,'components list'!$N$1:$AM$10000,4,FALSE())),"") | N54: =IFNA(IF(ISBLANK($A54),"",VLOOKUP($A54,'components list'!$N$1:$AM$10000,3,FALSE())),"") | O54: =if(isnumber(L54),MAX(0,rounddown(M54/C54,0)),"") | P54: =if(O54>=$N$1,"OK","NOK") -> OK | Q54: =if(isnumber(L54),max(0,rounddown((M54-VLOOKUP($D54,'components list'!$A$1:$G$1000,5,FALSE()))/C54,0)),"") | R54: =if(Q54>=$N$1,"OK","NOK") -> OK

Sheet components list
A1: =IFERROR(__xludf.DUMMYFUNCTION("QUERY({IMPORTRANGE(""1c0Wh_HY_bz6y2l1Jr0D6rPmvKgyRPSEPphRE5ZAqndk"", ""components list!A1:G1000"")},""Select * where Col1 is not null order by Col1"")"),"CABLE: FFC / FPC 26WAY 0.5MM 152MM [MP-FFCA05261522A]") -> CABLE: FFC / FPC 26WAY 0.5MM 152MM [MP-FFCA05261522A] | B1: =IFERROR(__xludf.DUMMYFUNCTION("""COMPUTED_VALUE"""),"OEPS090005") -> OEPS090005 | C1: =IFERROR(__xludf.DUMMYFUNCTION("""COMPUTED_VALUE"""),"Cable") -> Cable | D1: =IFERROR(__xludf.DUMMYFUNCTION("""COMPUTED_VALUE"""),"MP-FFCA05261522A") -> MP-FFCA05261522A | E1: =IFERROR(__xludf.DUMMYFUNCTION("""COMPUTED_VALUE"""),0.0) -> 0 | F1: =IFERROR(__xludf.DUMMYFUNCTION("""COMPUTED_VALUE"""),"Farnell") -> Farnell | G1: =IFERROR(__xludf.DUMMYFUNCTION("""COMPUTED_VALUE"""),"3385235") -> 3385235 | N1: =IFERROR(__xludf.DUMMYFUNCTION("QUERY({IMPORTRANGE(""1dWr6i50GOcTrOp-NGoVf4u5xOoCU2OQ0bHLlZMtKXgw"", ""components list!A1:Z1000"")},""Select * where Col1 is not null order by Col1"")"),"OEPS OEPS A35 001 OEPS A35 002 OEPS A35 003") -> OEPS OEPS A35 001 OEPS A35 002 OEPS A35 003 | O1: =IFERROR(__xludf.DUMMYFUNCTION("""COMPUTED_VALUE"""),"PDB-C156 TMK105B7104KVHF CL05B103KA5NNNC EMK212ABJ106MG-T") -> PDB-C156 TMK105B7104KVHF CL05B103KA5NNNC EMK212ABJ106MG-T | P1: =IFERROR(__xludf.DUMMYFUNCTION("""COMPUTED_VALUE""")," ") | Q1: =IFERROR(__xludf.DUMMYFUNCTION("""COMPUTED_VALUE""")," ") | R1: =IFERROR(__xludf.DUMMYFUNCTION("""COMPUTED_VALUE""")," ") | S1: =IFERROR(__xludf.DUMMYFUNCTION("""COMPUTED_VALUE""")," ") | T1: =IFERROR(__xludf.DUMMYFUNCTION("""COMPUTED_VALUE""")," ") | U1: =IFERROR(__xludf.DUMMYFUNCTION("""COMPUTED_VALUE""")," ") | V1: =IFERROR(__xludf.DUMMYFUNCTION("""COMPUTED_VALUE""")," ") | W1: =IFERROR(__xludf.DUMMYFUNCTION("""COMPUTED_VALUE""")," ") | ... AM1: =IFERROR(__xludf.DUMMYFUNCTION("""COMPUTED_VALUE""")," ")
A2: =IFERROR(__xludf.DUMMYFUNCTION("""COMPUTED_VALUE"""),"CABLE: FPC 0.30MM 17WAYS 2INCH [0150150217]") -> CABLE: FPC 0.30MM 17WAYS 2INCH [0150150217] | B2: =IFERROR(__xludf.DUMMYFUNCTION("""COMPUTED_VALUE"""),"OEPS090009") -> OEPS090009 | C2: =IFERROR(__xludf.DUMMYFUNCTION("""COMPUTED_VALUE"""),"Cable") -> Cable | D2: =IFERROR(__xludf.DUMMYFUNCTION("""COMPUTED_VALUE"""),"0150150217") -> 0150150217 | E2: =IFERROR(__xludf.DUMMYFUNCTION("""COMPUTED_VALUE"""),0.0) -> 0 | F2: =IFERROR(__xludf.DUMMYFUNCTION("""COMPUTED_VALUE"""),"DigiKey") -> DigiKey | G2: =IFERROR(__xludf.DUMMYFUNCTION("""COMPUTED_VALUE"""),"900-0150150217-ND") -> 900-0150150217-ND | N2: =IFERROR(__xludf.DUMMYFUNCTION("""COMPUTED_VALUE"""),"OEPS A35 004") -> OEPS A35 004 | O2: =IFERROR(__xludf.DUMMYFUNCTION("""COMPUTED_VALUE"""),"C3225X7R1C226K250AC") -> C3225X7R1C226K250AC | P2: =IFERROR(__xludf.DUMMYFUNCTION("""COMPUTED_VALUE"""),"650(R) 378(R) ") -> 650(R) 378(R) | Q2: =IFERROR(__xludf.DUMMYFUNCTION("""COMPUTED_VALUE"""),1028.0) -> 1028 | R2: =IFERROR(__xludf.DUMMYFUNCTION("""COMPUTED_VALUE"""),650.0) -> 650 | S2: =IFERROR(__xludf.DUMMYFUNCTION("""COMPUTED_VALUE"""),"Reel") -> Reel | T2: =IFERROR(__xludf.DUMMYFUNCTION("""COMPUTED_VALUE"""),"0622") -> 0622 | U2: =IFERROR(__xludf.DUMMYFUNCTION("""COMPUTED_VALUE"""),378.0) -> 378 | V2: =IFERROR(__xludf.DUMMYFUNCTION("""COMPUTED_VALUE"""),"Reel") -> Reel | W2: =IFERROR(__xludf.DUMMYFUNCTION("""COMPUTED_VALUE"""),"XXXX") -> XXXX
A3: =IFERROR(__xludf.DUMMYFUNCTION("""COMPUTED_VALUE"""),"CABLE: FPC 0.30MM 17WAYS 6INCH [0150150617]") -> CABLE: FPC 0.30MM 17WAYS 6INCH [0150150617] | B3: =IFERROR(__xludf.DUMMYFUNCTION("""COMPUTED_VALUE"""),"OEPS090008") -> OEPS090008 | C3: =IFERROR(__xludf.DUMMYFUNCTION("""COMPUTED_VALUE"""),"Cable") -> Cable | D3: =IFERROR(__xludf.DUMMYFUNCTION("""COMPUTED_VALUE"""),"0150150617") -> 0150150617 | E3: =IFERROR(__xludf.DUMMYFUNCTION("""COMPUTED_VALUE"""),0.0) -> 0 | F3: =IFERROR(__xludf.DUMMYFUNCTION("""COMPUTED_VALUE"""),"DigiKey") -> DigiKey | G3: =IFERROR(__xludf.DUMMYFUNCTION("""COMPUTED_VALUE"""),"900-0150150617-ND") -> 900-0150150617-ND | N3: =IFERROR(__xludf.DUMMYFUNCTION("""COMPUTED_VALUE"""),"OEPS A35 005") -> OEPS A35 005 | O3: =IFERROR(__xludf.DUMMYFUNCTION("""COMPUTED_VALUE"""),"UMK107BJ105KA-T") -> UMK107BJ105KA-T
A4: =IFERROR(__xludf.DUMMYFUNCTION("""COMPUTED_VALUE"""),"CABLE: FPC 0.30MM 27WAYS 2INCH [0150150227]") -> CABLE: FPC 0.30MM 27WAYS 2INCH [0150150227] | B4: =IFERROR(__xludf.DUMMYFUNCTION("""COMPUTED_VALUE"""),"OEPS090012") -> OEPS090012 | C4: =IFERROR(__xludf.DUMMYFUNCTION("""COMPUTED_VALUE"""),"Cable") -> Cable | D4: =IFERROR(__xludf.DUMMYFUNCTION("""COMPUTED_VALUE"""),"0150150227") -> 0150150227 | E4: =IFERROR(__xludf.DUMMYFUNCTION("""COMPUTED_VALUE"""),0.0) -> 0 | F4: =IFERROR(__xludf.DUMMYFUNCTION("""COMPUTED_VALUE"""),"DigiKey") -> DigiKey | G4: =IFERROR(__xludf.DUMMYFUNCTION("""COMPUTED_VALUE"""),"WM9645-ND") -> WM9645-ND | N4: =IFERROR(__xludf.DUMMYFUNCTION("""COMPUTED_VALUE"""),"OEPS A35 006") -> OEPS A35 006 | O4: =IFERROR(__xludf.DUMMYFUNCTION("""COMPUTED_VALUE"""),"C1005X5R1E474K050BE") -> C1005X5R1E474K050BE
A5: =IFERROR(__xludf.DUMMYFUNCTION("""COMPUTED_VALUE"""),"CABLE: FPC 0.30MM 27WAYS 4INCH [0150150427]") -> CABLE: FPC 0.30MM 27WAYS 4INCH [0150150427] | B5: =IFERROR(__xludf.DUMMYFUNCTION("""COMPUTED_VALUE"""),"OEPS090013") -> OEPS090013 | C5: =IFERROR(__xludf.DUMMYFUNCTION("""COMPUTED_VALUE"""),"Cable") -> Cable | D5: =IFERROR(__xludf.DUMMYFUNCTION("""COMPUTED_VALUE"""),"0150150427") -> 0150150427 | E5: =IFERROR(__xludf.DUMMYFUNCTION("""COMPUTED_VALUE"""),0.0) -> 0 | F5: =IFERROR(__xludf.DUMMYFUNCTION("""COMPUTED_VALUE"""),"DigiKey") -> DigiKey | G5: =IFERROR(__xludf.DUMMYFUNCTION("""COMPUTED_VALUE"""),"WM6669-ND") -> WM6669-ND | N5: =IFERROR(__xludf.DUMMYFUNCTION("""COMPUTED_VALUE"""),"OEPS A35 008") -> OEPS A35 008 | O5: =IFERROR(__xludf.DUMMYFUNCTION("""COMPUTED_VALUE"""),"GRM1555C1H220FA01D") -> GRM1555C1H220FA01D
A6: =IFERROR(__xludf.DUMMYFUNCTION("""COMPUTED_VALUE"""),"CABLE: FPC 0.30MM 45WAYS 2INCH [0150150245]") -> CABLE: FPC 0.30MM 45WAYS 2INCH [0150150245] | B6: =IFERROR(__xludf.DUMMYFUNCTION("""COMPUTED_VALUE"""),"OEPS090010") -> OEPS090010 | C6: =IFERROR(__xludf.DUMMYFUNCTION("""COMPUTED_VALUE"""),"Cable") -> Cable | D6: =IFERROR(__xludf.DUMMYFUNCTION("""COMPUTED_VALUE"""),"0150150245") -> 0150150245 | E6: =IFERROR(__xludf.DUMMYFUNCTION("""COMPUTED_VALUE"""),0.0) -> 0 | F6: =IFERROR(__xludf.DUMMYFUNCTION("""COMPUTED_VALUE"""),"DigiKey") -> DigiKey | G6: =IFERROR(__xludf.DUMMYFUNCTION("""COMPUTED_VALUE"""),"WM9648-ND") -> WM9648-ND | N6: =IFERROR(__xludf.DUMMYFUNCTION("""COMPUTED_VALUE"""),"OEPS A35 009") -> OEPS A35 009 | O6: =IFERROR(__xludf.DUMMYFUNCTION("""COMPUTED_VALUE"""),"GRM155R71H682JA88D") -> GRM155R71H682JA88D
A7: =IFERROR(__xludf.DUMMYFUNCTION("""COMPUTED_VALUE"""),"CABLE: FPC 0.30MM 45WAYS 4INCH [0150150445]") -> CABLE: FPC 0.30MM 45WAYS 4INCH [0150150445] | B7: =IFERROR(__xludf.DUMMYFUNCTION("""COMPUTED_VALUE"""),"OEPS090011") -> OEPS090011 | C7: =IFERROR(__xludf.DUMMYFUNCTION("""COMPUTED_VALUE"""),"Cable") -> Cable | D7: =IFERROR(__xludf.DUMMYFUNCTION("""COMPUTED_VALUE"""),"0150150445") -> 0150150445 | E7: =IFERROR(__xludf.DUMMYFUNCTION("""COMPUTED_VALUE"""),0.0) -> 0 | F7: =IFERROR(__xludf.DUMMYFUNCTION("""COMPUTED_VALUE"""),"DigiKey") -> DigiKey | G7: =IFERROR(__xludf.DUMMYFUNCTION("""COMPUTED_VALUE"""),"WM13117-ND") -> WM13117-ND | N7: =IFERROR(__xludf.DUMMYFUNCTION("""COMPUTED_VALUE"""),"OEPS A35 010") -> OEPS A35 010 | O7: =IFERROR(__xludf.DUMMYFUNCTION("""COMPUTED_VALUE"""),"CL21A475KAQNNNE") -> CL21A475KAQNNNE
A8: =IFERROR(__xludf.DUMMYFUNCTION("""COMPUTED_VALUE"""),"CABLE: MMCX-to-MMCX 2.13meter [523-265101-08-84.00]") -> CABLE: MMCX-to-MMCX 2.13meter [523-265101-08-84.00] | B8: =IFERROR(__xludf.DUMMYFUNCTION("""COMPUTED_VALUE"""),"OEPS090002") -> OEPS090002 | C8: =IFERROR(__xludf.DUMMYFUNCTION("""COMPUTED_VALUE"""),"Cable") -> Cable | D8: =IFERROR(__xludf.DUMMYFUNCTION("""COMPUTED_VALUE"""),"523-265101-08-84.00") -> 523-265101-08-84.00 | E8: =IFERROR(__xludf.DUMMYFUNCTION("""COMPUTED_VALUE"""),1.0) -> 1 | F8: =IFERROR(__xludf.DUMMYFUNCTION("""COMPUTED_VALUE"""),"DigiKey") -> DigiKey | G8: =IFERROR(__xludf.DUMMYFUNCTION("""COMPUTED_VALUE"""),"265101-08-84.00") -> 265101-08-84.00 | N8: =IFERROR(__xludf.DUMMYFUNCTION("""COMPUTED_VALUE"""),"OEPS A35 011") -> OEPS A35 011 | O8: =IFERROR(__xludf.DUMMYFUNCTION("""COMPUTED_VALUE"""),"GRM1555C1H180FA01D") -> GRM1555C1H180FA01D | P8: =IFERROR(__xludf.DUMMYFUNCTION("""COMPUTED_VALUE""")," ")
A9: =IFERROR(__xludf.DUMMYFUNCTION("""COMPUTED_VALUE"""),"CABLE: RIBON 10COND 28AWG GRAY 100FT 30.48meter [3365/10 100]") -> CABLE: RIBON 10COND 28AWG GRAY 100FT 30.48meter [3365/10 100] | B9: =IFERROR(__xludf.DUMMYFUNCTION("""COMPUTED_VALUE"""),"OEPS090003") -> OEPS090003 | C9: =IFERROR(__xludf.DUMMYFUNCTION("""COMPUTED_VALUE"""),"Cable") -> Cable | D9: =IFERROR(__xludf.DUMMYFUNCTION("""COMPUTED_VALUE"""),"3365/10 100") -> 3365/10 100 | E9: =IFERROR(__xludf.DUMMYFUNCTION("""COMPUTED_VALUE"""),0.0) -> 0 | F9: =IFERROR(__xludf.DUMMYFUNCTION("""COMPUTED_VALUE"""),"DigiKey") -> DigiKey | G9: =IFERROR(__xludf.DUMMYFUNCTION("""COMPUTED_VALUE"""),"3M157849-100-ND") -> 3M157849-100-ND | N9: =IFERROR(__xludf.DUMMYFUNCTION("""COMPUTED_VALUE"""),"OEPS A35 012") -> OEPS A35 012 | O9: =IFERROR(__xludf.DUMMYFUNCTION("""COMPUTED_VALUE"""),"T495C107K016ATE200") -> T495C107K016ATE200
A10: =IFERROR(__xludf.DUMMYFUNCTION("""COMPUTED_VALUE"""),"CABLE: RIBON 14COND 28AWG GRAY 100FT 30.48meter [3365/14 100]") -> CABLE: RIBON 14COND 28AWG GRAY 100FT 30.48meter [3365/14 100] | B10: =IFERROR(__xludf.DUMMYFUNCTION("""COMPUTED_VALUE"""),"OEPS090007") -> OEPS090007 | C10: =IFERROR(__xludf.DUMMYFUNCTION("""COMPUTED_VALUE"""),"Cable") -> Cable | D10: =IFERROR(__xludf.DUMMYFUNCTION("""COMPUTED_VALUE"""),"3365/14 100") -> 3365/14 100 | E10: =IFERROR(__xludf.DUMMYFUNCTION("""COMPUTED_VALUE"""),0.0) -> 0 | F10: =IFERROR(__xludf.DUMMYFUNCTION("""COMPUTED_VALUE"""),"DigiKey") -> DigiKey | G10: =IFERROR(__xludf.DUMMYFUNCTION("""COMPUTED_VALUE"""),"3M157859-100-ND") -> 3M157859-100-ND | N10: =IFERROR(__xludf.DUMMYFUNCTION("""COMPUTED_VALUE"""),"OEPS A35 013") -> OEPS A35 013 | O10: =IFERROR(__xludf.DUMMYFUNCTION("""COMPUTED_VALUE"""),"GRM1555C1H100FA01D") -> GRM1555C1H100FA01D
A11: =IFERROR(__xludf.DUMMYFUNCTION("""COMPUTED_VALUE"""),"CABLE: RIBON 8COND WHITE 4INCH 0.1016meter [A08SUR08SUR32W102A]") -> CABLE: RIBON 8COND WHITE 4INCH 0.1016meter [A08SUR08SUR32W102A] | B11: =IFERROR(__xludf.DUMMYFUNCTION("""COMPUTED_VALUE"""),"OEPS090004") -> OEPS090004 | C11: =IFERROR(__xludf.DUMMYFUNCTION("""COMPUTED_VALUE"""),"Cable") -> Cable | D11: =IFERROR(__xludf.DUMMYFUNCTION("""COMPUTED_VALUE"""),"A08SUR08SUR32W102A") -> A08SUR08SUR32W102A | E11: =IFERROR(__xludf.DUMMYFUNCTION("""COMPUTED_VALUE"""),0.0) -> 0 | F11: =IFERROR(__xludf.DUMMYFUNCTION("""COMPUTED_VALUE"""),"DigiKey") -> DigiKey | G11: =IFERROR(__xludf.DUMMYFUNCTION("""COMPUTED_VALUE"""),"455-4058-ND") -> 455-4058-ND | N11: =IFERROR(__xludf.DUMMYFUNCTION("""COMPUTED_VALUE"""),"OEPS A35 014") -> OEPS A35 014 | O11: =IFERROR(__xludf.DUMMYFUNCTION("""COMPUTED_VALUE"""),"RC0402FR-1310KL") -> RC0402FR-1310KL
A12: =IFERROR(__xludf.DUMMYFUNCTION("""COMPUTED_VALUE"""),"CABLE: SDR 2meter 26POS [1SD26-3120-00C-200]") -> CABLE: SDR 2meter 26POS [1SD26-3120-00C-200] | B12: =IFERROR(__xludf.DUMMYFUNCTION("""COMPUTED_VALUE"""),"OEPS090001") -> OEPS090001 | C12: =IFERROR(__xludf.DUMMYFUNCTION("""COMPUTED_VALUE"""),"Cable") -> Cable | D12: =IFERROR(__xludf.DUMMYFUNCTION("""COMPUTED_VALUE"""),"1SD26-3120-00C-200") -> 1SD26-3120-00C-200 | E12: =IFERROR(__xludf.DUMMYFUNCTION("""COMPUTED_VALUE"""),1.0) -> 1 | F12: =IFERROR(__xludf.DUMMYFUNCTION("""COMPUTED_VALUE"""),"DigiKey") -> DigiKey | G12: =IFERROR(__xludf.DUMMYFUNCTION("""COMPUTED_VALUE"""),"3M155828-ND") -> 3M155828-ND | N12: =IFERROR(__xludf.DUMMYFUNCTION("""COMPUTED_VALUE"""),"OEPS A35 015") -> OEPS A35 015 | O12: =IFERROR(__xludf.DUMMYFUNCTION("""COMPUTED_VALUE"""),"RC0402FR-071KL") -> RC0402FR-071KL
A13: =IFERROR(__xludf.DUMMYFUNCTION("""COMPUTED_VALUE"""),"CABLE: Stereo Jack Plug to Plug 3,5 MM 3.3ft (1.0m) [PSG03744]") -> CABLE: Stereo Jack Plug to Plug 3,5 MM 3.3ft (1.0m) [PSG03744] | B13: =IFERROR(__xludf.DUMMYFUNCTION("""COMPUTED_VALUE"""),"OEPS090006") -> OEPS090006 | C13: =IFERROR(__xludf.DUMMYFUNCTION("""COMPUTED_VALUE"""),"Cable") -> Cable | D13: =IFERROR(__xludf.DUMMYFUNCTION("""COMPUTED_VALUE"""),"PSG03744") -> PSG03744 | E13: =IFERROR(__xludf.DUMMYFUNCTION("""COMPUTED_VALUE"""),0.0) -> 0 | F13: =IFERROR(__xludf.DUMMYFUNCTION("""COMPUTED_VALUE"""),"Farnell") -> Farnell | G13: =IFERROR(__xludf.DUMMYFUNCTION("""COMPUTED_VALUE"""),"3498200") -> 3498200 | N13: =IFERROR(__xludf.DUMMYFUNCTION("""COMPUTED_VALUE"""),"OEPS A35 016") -> OEPS A35 016 | O13: =IFERROR(__xludf.DUMMYFUNCTION("""COMPUTED_VALUE"""),"RC0402FR-074K7L") -> RC0402FR-074K7L
A14: =IFERROR(__xludf.DUMMYFUNCTION("""COMPUTED_VALUE"""),"CAPACITOR POL: SMD ALUM 1000uF 6.3V ±20% X7R [MCVVT6R3M102FB3L] [SMD]") -> CAPACITOR POL: SMD ALUM 1000uF 6.3V ±20% X7R [MCVVT6R3M102FB3L] [SMD] | B14: =IFERROR(__xludf.DUMMYFUNCTION("""COMPUTED_VALUE"""),"OEPS210009") -> OEPS210009 | C14: =IFERROR(__xludf.DUMMYFUNCTION("""COMPUTED_VALUE"""),"SMD") -> SMD | D14: =IFERROR(__xludf.DUMMYFUNCTION("""COMPUTED_VALUE"""),"MCVVT6R3M102FB3L") -> MCVVT6R3M102FB3L | E14: =IFERROR(__xludf.DUMMYFUNCTION("""COMPUTED_VALUE"""),5.0) -> 5 | F14: =IFERROR(__xludf.DUMMYFUNCTION("""COMPUTED_VALUE"""),"Farnell") -> Farnell | G14: =IFERROR(__xludf.DUMMYFUNCTION("""COMPUTED_VALUE"""),"2611416") -> 2611416 | N14: =IFERROR(__xludf.DUMMYFUNCTION("""COMPUTED_VALUE"""),"OEPS A35 017") -> OEPS A35 017 | O14: =IFERROR(__xludf.DUMMYFUNCTION("""COMPUTED_VALUE"""),"RC0402FR-070RL") -> RC0402FR-070RL | P14: =IFERROR(__xludf.DUMMYFUNCTION("""COMPUTED_VALUE"""),"91(R) ") -> 91(R) | Q14: =IFERROR(__xludf.DUMMYFUNCTION("""COMPUTED_VALUE"""),91.0) -> 91 | R14: =IFERROR(__xludf.DUMMYFUNCTION("""COMPUTED_VALUE"""),91.0) -> 91 | S14: =IFERROR(__xludf.DUMMYFUNCTION("""COMPUTED_VALUE"""),"Reel") -> Reel | T14: =IFERROR(__xludf.DUMMYFUNCTION("""COMPUTED_VALUE"""),"0622") -> 0622
A15: =IFERROR(__xludf.DUMMYFUNCTION("""COMPUTED_VALUE"""),"CAPACITOR POL: SMD ALUM 100uF 25V ±20% X7R [UCD1E101MCL6GS] [SMD]") -> CAPACITOR POL: SMD ALUM 100uF 25V ±20% X7R [UCD1E101MCL6GS] [SMD] | B15: =IFERROR(__xludf.DUMMYFUNCTION("""COMPUTED_VALUE"""),"OEPS210012") -> OEPS210012 | C15: =IFERROR(__xludf.DUMMYFUNCTION("""COMPUTED_VALUE"""),"SMD") -> SMD | D15: =IFERROR(__xludf.DUMMYFUNCTION("""COMPUTED_VALUE"""),"UCD1E101MCL6GS") -> UCD1E101MCL6GS | E15: =IFERROR(__xludf.DUMMYFUNCTION("""COMPUTED_VALUE"""),2.0) -> 2 | F15: =IFERROR(__xludf.DUMMYFUNCTION("""COMPUTED_VALUE"""),"DigiKey") -> DigiKey | G15: =IFERROR(__xludf.DUMMYFUNCTION("""COMPUTED_VALUE"""),"493-6198-6-ND") -> 493-6198-6-ND | N15: =IFERROR(__xludf.DUMMYFUNCTION("""COMPUTED_VALUE"""),"OEPS A35 019") -> OEPS A35 019 | O15: =IFERROR(__xludf.DUMMYFUNCTION("""COMPUTED_VALUE"""),"RN731ETTP50R0F50") -> RN731ETTP50R0F50 | P15: =IFERROR(__xludf.DUMMYFUNCTION("""COMPUTED_VALUE"""),"58(R) ") -> 58(R) | Q15: =IFERROR(__xludf.DUMMYFUNCTION("""COMPUTED_VALUE"""),58.0) -> 58 | R15: =IFERROR(__xludf.DUMMYFUNCTION("""COMPUTED_VALUE"""),58.0) -> 58 | S15: =IFERROR(__xludf.DUMMYFUNCTION("""COMPUTED_VALUE"""),"Reel") -> Reel | T15: =IFERROR(__xludf.DUMMYFUNCTION("""COMPUTED_VALUE"""),"0622") -> 0622
A16: =IFERROR(__xludf.DUMMYFUNCTION("""COMPUTED_VALUE"""),"CAPACITOR POL: SMD TANT A 1206 100uF 10V ±20% 1.4Ohm [TLJA107M010R1400] [SMD]") -> CAPACITOR POL: SMD TANT A 1206 100uF 10V ±20% 1.4Ohm [TLJA107M010R1400] [SMD] | B16: =IFERROR(__xludf.DUMMYFUNCTION("""COMPUTED_VALUE"""),"OEPS210002") -> OEPS210002 | C16: =IFERROR(__xludf.DUMMYFUNCTION("""COMPUTED_VALUE"""),"SMD") -> SMD | D16: =IFERROR(__xludf.DUMMYFUNCTION("""COMPUTED_VALUE"""),"TLJA107M010R1400") -> TLJA107M010R1400 | E16: =IFERROR(__xludf.DUMMYFUNCTION("""COMPUTED_VALUE"""),5.0) -> 5 | F16: =IFERROR(__xludf.DUMMYFUNCTION("""COMPUTED_VALUE"""),"DigiKey") -> DigiKey | G16: =IFERROR(__xludf.DUMMYFUNCTION("""COMPUTED_VALUE"""),"478-5651-6-ND") -> 478-5651-6-ND | N16: =IFERROR(__xludf.DUMMYFUNCTION("""COMPUTED_VALUE"""),"OEPS A35 020") -> OEPS A35 020 | O16: =IFERROR(__xludf.DUMMYFUNCTION("""COMPUTED_VALUE"""),"RC0402FR-07240RL") -> RC0402FR-07240RL | P16: =IFERROR(__xludf.DUMMYFUNCTION("""COMPUTED_VALUE"""),"506(R) ") -> 506(R) | Q16: =IFERROR(__xludf.DUMMYFUNCTION("""COMPUTED_VALUE"""),506.0) -> 506 | R16: =IFERROR(__xludf.DUMMYFUNCTION("""COMPUTED_VALUE"""),506.0) -> 506 | S16: =IFERROR(__xludf.DUMMYFUNCTION("""COMPUTED_VALUE"""),"Reel") -> Reel | T16: =IFERROR(__xludf.DUMMYFUNCTION("""COMPUTED_VALUE"""),"0622") -> 0622
A17: =IFERROR(__xludf.DUMMYFUNCTION("""COMPUTED_VALUE"""),"CAPACITOR POL: SMD TANT A 1206 4.7uF 16V ±10% [TAJA475K016UNJ] [SMD]") -> CAPACITOR POL: SMD TANT A 1206 4.7uF 16V ±10% [TAJA475K016UNJ] [SMD] | B17: =IFERROR(__xludf.DUMMYFUNCTION("""COMPUTED_VALUE"""),"OEPS210003") -> OEPS210003 | C17: =IFERROR(__xludf.DUMMYFUNCTION("""COMPUTED_VALUE"""),"SMD") -> SMD | D17: =IFERROR(__xludf.DUMMYFUNCTION("""COMPUTED_VALUE"""),"TAJA475K016UNJ") -> TAJA475K016UNJ | E17: =IFERROR(__xludf.DUMMYFUNCTION("""COMPUTED_VALUE"""),5.0) -> 5 | F17: =IFERROR(__xludf.DUMMYFUNCTION("""COMPUTED_VALUE"""),"DigiKey") -> DigiKey | G17: =IFERROR(__xludf.DUMMYFUNCTION("""COMPUTED_VALUE"""),"478-11461-6-ND") -> 478-11461-6-ND | N17: =IFERROR(__xludf.DUMMYFUNCTION("""COMPUTED_VALUE"""),"OEPS A35 021") -> OEPS A35 021 | O17: =IFERROR(__xludf.DUMMYFUNCTION("""COMPUTED_VALUE"""),"RC0402FR-071K6L") -> RC0402FR-071K6L | P17: =IFERROR(__xludf.DUMMYFUNCTION("""COMPUTED_VALUE"""),"503(R) ") -> 503(R) | Q17: =IFERROR(__xludf.DUMMYFUNCTION("""COMPUTED_VALUE"""),503.0) -> 503 | R17: =IFERROR(__xludf.DUMMYFUNCTION("""COMPUTED_VALUE"""),503.0) -> 503 | S17: =IFERROR(__xludf.DUMMYFUNCTION("""COMPUTED_VALUE"""),"Reel") -> Reel | T17: =IFERROR(__xludf.DUMMYFUNCTION("""COMPUTED_VALUE"""),"0622") -> 0622
A18: =IFERROR(__xludf.DUMMYFUNCTION("""COMPUTED_VALUE"""),"CAPACITOR POL: SMD TANT B0 1411 33uF 20V ±20% 50Ohm [TL8B0336M020C] [SMD]") -> CAPACITOR POL: SMD TANT B0 1411 33uF 20V ±20% 50Ohm [TL8B0336M020C] [SMD] | B18: =IFERROR(__xludf.DUMMYFUNCTION("""COMPUTED_VALUE"""),"OEPS210010") -> OEPS210010 | C18: =IFERROR(__xludf.DUMMYFUNCTION("""COMPUTED_VALUE"""),"SMD") -> SMD | D18: =IFERROR(__xludf.DUMMYFUNCTION("""COMPUTED_VALUE"""),"TL8B0336M020C") -> TL8B0336M020C | E18: =IFERROR(__xludf.DUMMYFUNCTION("""COMPUTED_VALUE"""),5.0) -> 5 | F18: =IFERROR(__xludf.DUMMYFUNCTION("""COMPUTED_VALUE"""),"Digikey") -> Digikey | G18: =IFERROR(__xludf.DUMMYFUNCTION("""COMPUTED_VALUE"""),"718-1918-6-ND") -> 718-1918-6-ND | N18: =IFERROR(__xludf.DUMMYFUNCTION("""COMPUTED_VALUE"""),"OEPS A35 022") -> OEPS A35 022 | O18: =IFERROR(__xludf.DUMMYFUNCTION("""COMPUTED_VALUE"""),"RC0402FR-0740K2L") -> RC0402FR-0740K2L
A19: =IFERROR(__xludf.DUMMYFUNCTION("""COMPUTED_VALUE"""),"CAPACITOR POL: SMD TANT D 2917 100uF 16V ±10% 700mOhm [T491D107K016AT7280] [SMD]") -> CAPACITOR POL: SMD TANT D 2917 100uF 16V ±10% 700mOhm [T491D107K016AT7280] [SMD] | B19: =IFERROR(__xludf.DUMMYFUNCTION("""COMPUTED_VALUE"""),"OEPS210004") -> OEPS210004 | C19: =IFERROR(__xludf.DUMMYFUNCTION("""COMPUTED_VALUE"""),"SMD") -> SMD | D19: =IFERROR(__xludf.DUMMYFUNCTION("""COMPUTED_VALUE"""),"T491D107K016AT7280") -> T491D107K016AT7280 | E19: =IFERROR(__xludf.DUMMYFUNCTION("""COMPUTED_VALUE"""),3.0) -> 3 | F19: =IFERROR(__xludf.DUMMYFUNCTION("""COMPUTED_VALUE"""),"DigiKey") -> DigiKey | G19: =IFERROR(__xludf.DUMMYFUNCTION("""COMPUTED_VALUE"""),"399-18066-6-ND") -> 399-18066-6-ND | N19: =IFERROR(__xludf.DUMMYFUNCTION("""COMPUTED_VALUE"""),"OEPS A35 023") -> OEPS A35 023 | O19: =IFERROR(__xludf.DUMMYFUNCTION("""COMPUTED_VALUE"""),"RC0402FR-07665KL") -> RC0402FR-07665KL
A20: =IFERROR(__xludf.DUMMYFUNCTION("""COMPUTED_VALUE"""),"CAPACITOR POL: SMD TANT D 2917 330uF 10V ±10% 65mOhm (OEPS J30 011A) [TPSD337K010R0065] [SMD]") -> CAPACITOR POL: SMD TANT D 2917 330uF 10V ±10% 65mOhm (OEPS J30 011A) [TPSD337K010R0065] [SMD] | B20: =IFERROR(__xludf.DUMMYFUNCTION("""COMPUTED_VALUE"""),"OEPS210008") -> OEPS210008 | C20: =IFERROR(__xludf.DUMMYFUNCTION("""COMPUTED_VALUE"""),"SMD") -> SMD | D20: =IFERROR(__xludf.DUMMYFUNCTION("""COMPUTED_VALUE"""),"TPSD337K010R0065") -> TPSD337K010R0065 | E20: =IFERROR(__xludf.DUMMYFUNCTION("""COMPUTED_VALUE"""),5.0) -> 5 | F20: =IFERROR(__xludf.DUMMYFUNCTION("""COMPUTED_VALUE"""),"Digikey") -> Digikey | G20: =IFERROR(__xludf.DUMMYFUNCTION("""COMPUTED_VALUE"""),"478-9190-6-ND") -> 478-9190-6-ND | N20: =IFERROR(__xludf.DUMMYFUNCTION("""COMPUTED_VALUE"""),"OEPS A35 024") -> OEPS A35 024 | O20: =IFERROR(__xludf.DUMMYFUNCTION("""COMPUTED_VALUE"""),"RC0402FR-07357KL") -> RC0402FR-07357KL
A21: =IFERROR(__xludf.DUMMYFUNCTION("""COMPUTED_VALUE"""),"CAPACITOR POL: SMD TANT X 100uF 16V ±10% 75mOhm [T498X107K016ATE075] [SMD]") -> CAPACITOR POL: SMD TANT X 100uF 16V ±10% 75mOhm [T498X107K016ATE075] [SMD] | B21: =IFERROR(__xludf.DUMMYFUNCTION("""COMPUTED_VALUE"""),"OEPS210001") -> OEPS210001 | C21: =IFERROR(__xludf.DUMMYFUNCTION("""COMPUTED_VALUE"""),"SMD") -> SMD | D21: =IFERROR(__xludf.DUMMYFUNCTION("""COMPUTED_VALUE"""),"T498X107K016ATE075") -> T498X107K016ATE075 | E21: =IFERROR(__xludf.DUMMYFUNCTION("""COMPUTED_VALUE"""),3.0) -> 3 | F21: =IFERROR(__xludf.DUMMYFUNCTION("""COMPUTED_VALUE"""),"DigiKey") -> DigiKey | G21: =IFERROR(__xludf.DUMMYFUNCTION("""COMPUTED_VALUE"""),"399-5207-6-ND") -> 399-5207-6-ND | N21: =IFERROR(__xludf.DUMMYFUNCTION("""COMPUTED_VALUE"""),"OEPS A35 025") -> OEPS A35 025 | O21: =IFERROR(__xludf.DUMMYFUNCTION("""COMPUTED_VALUE"""),"RC0402FR-0724K9L") -> RC0402FR-0724K9L
A22: =IFERROR(__xludf.DUMMYFUNCTION("""COMPUTED_VALUE"""),"CAPACITOR POL: TH ALUM 100uF 25V ±20% 130mOhm [EEU-FM1E101B] [TH]") -> CAPACITOR POL: TH ALUM 100uF 25V ±20% 130mOhm [EEU-FM1E101B] [TH] | B22: =IFERROR(__xludf.DUMMYFUNCTION("""COMPUTED_VALUE"""),"OEPS210005") -> OEPS210005 | C22: =IFERROR(__xludf.DUMMYFUNCTION("""COMPUTED_VALUE"""),"TH") -> TH | D22: =IFERROR(__xludf.DUMMYFUNCTION("""COMPUTED_VALUE"""),"EEU-FM1E101B") -> EEU-FM1E101B | E22: =IFERROR(__xludf.DUMMYFUNCTION("""COMPUTED_VALUE"""),1.0) -> 1 | F22: =IFERROR(__xludf.DUMMYFUNCTION("""COMPUTED_VALUE"""),"DigiKey") -> DigiKey | G22: =IFERROR(__xludf.DUMMYFUNCTION("""COMPUTED_VALUE"""),"P19702CT-ND") -> P19702CT-ND | N22: =IFERROR(__xludf.DUMMYFUNCTION("""COMPUTED_VALUE"""),"OEPS A35 026") -> OEPS A35 026 | O22: =IFERROR(__xludf.DUMMYFUNCTION("""COMPUTED_VALUE"""),"RC0402FR-0778K7L") -> RC0402FR-0778K7L | P22: =IFERROR(__xludf.DUMMYFUNCTION("""COMPUTED_VALUE"""),"512(R) ") -> 512(R) | Q22: =IFERROR(__xludf.DUMMYFUNCTION("""COMPUTED_VALUE"""),512.0) -> 512 | R22: =IFERROR(__xludf.DUMMYFUNCTION("""COMPUTED_VALUE"""),512.0) -> 512 | S22: =IFERROR(__xludf.DUMMYFUNCTION("""COMPUTED_VALUE"""),"Reel") -> Reel | T22: =IFERROR(__xludf.DUMMYFUNCTION("""COMPUTED_VALUE"""),"0622") -> 0622
